{
    DataVersion: 3465,
    size: [12, 11, 12],
    data: [
        {pos: [8, 0, 8], state: "woot_revived:diamond_cell{attached:true,enabled:true}", nbt: {ForgeCaps: {}, InputTank: {Amount: 0, FluidName: "minecraft:empty"}, id: "woot_revived:diamond_cell"}},
        {pos: [8, 1, 8], state: "woot_revived:export{attached:true,enabled:true}", nbt: {ForgeCaps: {}, id: "woot_revived:export"}},
        {pos: [8, 2, 8], state: "woot_revived:import{attached:true,enabled:true}", nbt: {FluidHandler: [{IsNull: 0b, Stacks: []}, {IsNull: 1b}, {IsNull: 1b}, {IsNull: 1b}], ForgeCaps: {}, ItemHandler: [{IsNull: 0b, Stacks: []}, {IsNull: 1b}, {IsNull: 1b}, {IsNull: 1b}], id: "woot_revived:import"}},
        {pos: [8, 3, 8], state: "woot_revived:factory_connect{attached:true,enabled:true}", nbt: {ForgeCaps: {}, id: "woot_revived:factory_connect"}},
        {pos: [5, 4, 6], state: "woot_revived:diamond_plinth{attached:true,enabled:true}", nbt: {ForgeCaps: {}, id: "woot_revived:diamond_plinth"}},
        {pos: [5, 4, 7], state: "woot_revived:diamond_plinth{attached:true,enabled:true}", nbt: {ForgeCaps: {}, id: "woot_revived:diamond_plinth"}},
        {pos: [5, 4, 9], state: "woot_revived:diamond_plinth{attached:true,enabled:true}", nbt: {ForgeCaps: {}, id: "woot_revived:diamond_plinth"}},
        {pos: [5, 4, 10], state: "woot_revived:diamond_plinth{attached:true,enabled:true}", nbt: {ForgeCaps: {}, id: "woot_revived:diamond_plinth"}},
        {pos: [6, 4, 5], state: "woot_revived:diamond_plinth{attached:true,enabled:true}", nbt: {ForgeCaps: {}, id: "woot_revived:diamond_plinth"}},
        {pos: [6, 4, 6], state: "woot_revived:gold_plinth{attached:true,enabled:true}", nbt: {ForgeCaps: {}, id: "woot_revived:gold_plinth"}},
        {pos: [6, 4, 7], state: "woot_revived:gold_plinth{attached:true,enabled:true}", nbt: {ForgeCaps: {}, id: "woot_revived:gold_plinth"}},
        {pos: [6, 4, 8], state: "woot_revived:iron_plinth{attached:true,enabled:true}", nbt: {ForgeCaps: {}, id: "woot_revived:iron_plinth"}},
        {pos: [6, 4, 9], state: "woot_revived:gold_plinth{attached:true,enabled:true}", nbt: {ForgeCaps: {}, id: "woot_revived:gold_plinth"}},
        {pos: [6, 4, 10], state: "woot_revived:gold_plinth{attached:true,enabled:true}", nbt: {ForgeCaps: {}, id: "woot_revived:gold_plinth"}},
        {pos: [6, 4, 11], state: "woot_revived:diamond_plinth{attached:true,enabled:true}", nbt: {ForgeCaps: {}, id: "woot_revived:diamond_plinth"}},
        {pos: [7, 4, 5], state: "woot_revived:diamond_plinth{attached:true,enabled:true}", nbt: {ForgeCaps: {}, id: "woot_revived:diamond_plinth"}},
        {pos: [7, 4, 6], state: "woot_revived:gold_plinth{attached:true,enabled:true}", nbt: {ForgeCaps: {}, id: "woot_revived:gold_plinth"}},
        {pos: [7, 4, 7], state: "woot_revived:iron_plinth{attached:true,enabled:true}", nbt: {ForgeCaps: {}, id: "woot_revived:iron_plinth"}},
        {pos: [7, 4, 8], state: "woot_revived:copper_plinth{attached:true,enabled:true}", nbt: {ForgeCaps: {}, id: "woot_revived:copper_plinth"}},
        {pos: [7, 4, 9], state: "woot_revived:iron_plinth{attached:true,enabled:true}", nbt: {ForgeCaps: {}, id: "woot_revived:iron_plinth"}},
        {pos: [7, 4, 10], state: "woot_revived:gold_plinth{attached:true,enabled:true}", nbt: {ForgeCaps: {}, id: "woot_revived:gold_plinth"}},
        {pos: [7, 4, 11], state: "woot_revived:diamond_plinth{attached:true,enabled:true}", nbt: {ForgeCaps: {}, id: "woot_revived:diamond_plinth"}},
        {pos: [8, 4, 6], state: "woot_revived:iron_plinth{attached:true,enabled:true}", nbt: {ForgeCaps: {}, id: "woot_revived:iron_plinth"}},
        {pos: [8, 4, 7], state: "woot_revived:copper_plinth{attached:true,enabled:true}", nbt: {ForgeCaps: {}, id: "woot_revived:copper_plinth"}},
        {pos: [8, 4, 8], state: "woot_revived:copper_plinth{attached:true,enabled:true}", nbt: {ForgeCaps: {}, id: "woot_revived:copper_plinth"}},
        {pos: [8, 4, 9], state: "woot_revived:copper_plinth{attached:true,enabled:true}", nbt: {ForgeCaps: {}, id: "woot_revived:copper_plinth"}},
        {pos: [8, 4, 10], state: "woot_revived:iron_plinth{attached:true,enabled:true}", nbt: {ForgeCaps: {}, id: "woot_revived:iron_plinth"}},
        {pos: [9, 4, 5], state: "woot_revived:diamond_plinth{attached:true,enabled:true}", nbt: {ForgeCaps: {}, id: "woot_revived:diamond_plinth"}},
        {pos: [9, 4, 6], state: "woot_revived:gold_plinth{attached:true,enabled:true}", nbt: {ForgeCaps: {}, id: "woot_revived:gold_plinth"}},
        {pos: [9, 4, 7], state: "woot_revived:iron_plinth{attached:true,enabled:true}", nbt: {ForgeCaps: {}, id: "woot_revived:iron_plinth"}},
        {pos: [9, 4, 8], state: "woot_revived:copper_plinth{attached:true,enabled:true}", nbt: {ForgeCaps: {}, id: "woot_revived:copper_plinth"}},
        {pos: [9, 4, 9], state: "woot_revived:iron_plinth{attached:true,enabled:true}", nbt: {ForgeCaps: {}, id: "woot_revived:iron_plinth"}},
        {pos: [9, 4, 10], state: "woot_revived:gold_plinth{attached:true,enabled:true}", nbt: {ForgeCaps: {}, id: "woot_revived:gold_plinth"}},
        {pos: [9, 4, 11], state: "woot_revived:diamond_plinth{attached:true,enabled:true}", nbt: {ForgeCaps: {}, id: "woot_revived:diamond_plinth"}},
        {pos: [10, 4, 5], state: "woot_revived:diamond_plinth{attached:true,enabled:true}", nbt: {ForgeCaps: {}, id: "woot_revived:diamond_plinth"}},
        {pos: [10, 4, 6], state: "woot_revived:gold_plinth{attached:true,enabled:true}", nbt: {ForgeCaps: {}, id: "woot_revived:gold_plinth"}},
        {pos: [10, 4, 7], state: "woot_revived:gold_plinth{attached:true,enabled:true}", nbt: {ForgeCaps: {}, id: "woot_revived:gold_plinth"}},
        {pos: [10, 4, 8], state: "woot_revived:iron_plinth{attached:true,enabled:true}", nbt: {ForgeCaps: {}, id: "woot_revived:iron_plinth"}},
        {pos: [10, 4, 9], state: "woot_revived:gold_plinth{attached:true,enabled:true}", nbt: {ForgeCaps: {}, id: "woot_revived:gold_plinth"}},
        {pos: [10, 4, 10], state: "woot_revived:gold_plinth{attached:true,enabled:true}", nbt: {ForgeCaps: {}, id: "woot_revived:gold_plinth"}},
        {pos: [10, 4, 11], state: "woot_revived:diamond_plinth{attached:true,enabled:true}", nbt: {ForgeCaps: {}, id: "woot_revived:diamond_plinth"}},
        {pos: [11, 4, 6], state: "woot_revived:diamond_plinth{attached:true,enabled:true}", nbt: {ForgeCaps: {}, id: "woot_revived:diamond_plinth"}},
        {pos: [11, 4, 7], state: "woot_revived:diamond_plinth{attached:true,enabled:true}", nbt: {ForgeCaps: {}, id: "woot_revived:diamond_plinth"}},
        {pos: [11, 4, 9], state: "woot_revived:diamond_plinth{attached:true,enabled:true}", nbt: {ForgeCaps: {}, id: "woot_revived:diamond_plinth"}},
        {pos: [11, 4, 10], state: "woot_revived:diamond_plinth{attached:true,enabled:true}", nbt: {ForgeCaps: {}, id: "woot_revived:diamond_plinth"}},
        {pos: [5, 5, 6], state: "woot_revived:diamond_pylon{attached:true,enabled:true}", nbt: {ForgeCaps: {}, id: "woot_revived:diamond_pylon"}},
        {pos: [5, 5, 7], state: "woot_revived:diamond_pylon{attached:true,enabled:true}", nbt: {ForgeCaps: {}, id: "woot_revived:diamond_pylon"}},
        {pos: [5, 5, 9], state: "woot_revived:diamond_pylon{attached:true,enabled:true}", nbt: {ForgeCaps: {}, id: "woot_revived:diamond_pylon"}},
        {pos: [5, 5, 10], state: "woot_revived:diamond_pylon{attached:true,enabled:true}", nbt: {ForgeCaps: {}, id: "woot_revived:diamond_pylon"}},
        {pos: [6, 5, 5], state: "woot_revived:diamond_pylon{attached:true,enabled:true}", nbt: {ForgeCaps: {}, id: "woot_revived:diamond_pylon"}},
        {pos: [6, 5, 6], state: "woot_revived:gold_pylon{attached:true,enabled:true}", nbt: {ForgeCaps: {}, id: "woot_revived:gold_pylon"}},
        {pos: [6, 5, 7], state: "woot_revived:gold_pylon{attached:true,enabled:true}", nbt: {ForgeCaps: {}, id: "woot_revived:gold_pylon"}},
        {pos: [6, 5, 8], state: "woot_revived:iron_pylon{attached:true,enabled:true}", nbt: {ForgeCaps: {}, id: "woot_revived:iron_pylon"}},
        {pos: [6, 5, 9], state: "woot_revived:gold_pylon{attached:true,enabled:true}", nbt: {ForgeCaps: {}, id: "woot_revived:gold_pylon"}},
        {pos: [6, 5, 10], state: "woot_revived:gold_pylon{attached:true,enabled:true}", nbt: {ForgeCaps: {}, id: "woot_revived:gold_pylon"}},
        {pos: [6, 5, 11], state: "woot_revived:diamond_pylon{attached:true,enabled:true}", nbt: {ForgeCaps: {}, id: "woot_revived:diamond_pylon"}},
        {pos: [7, 5, 5], state: "woot_revived:diamond_pylon{attached:true,enabled:true}", nbt: {ForgeCaps: {}, id: "woot_revived:diamond_pylon"}},
        {pos: [7, 5, 6], state: "woot_revived:gold_pylon{attached:true,enabled:true}", nbt: {ForgeCaps: {}, id: "woot_revived:gold_pylon"}},
        {pos: [7, 5, 7], state: "woot_revived:iron_pylon{attached:true,enabled:true}", nbt: {ForgeCaps: {}, id: "woot_revived:iron_pylon"}},
        {pos: [7, 5, 8], state: "woot_revived:copper_pylon{attached:true,enabled:true}", nbt: {ForgeCaps: {}, id: "woot_revived:copper_pylon"}},
        {pos: [7, 5, 9], state: "woot_revived:iron_pylon{attached:true,enabled:true}", nbt: {ForgeCaps: {}, id: "woot_revived:iron_pylon"}},
        {pos: [7, 5, 10], state: "woot_revived:gold_pylon{attached:true,enabled:true}", nbt: {ForgeCaps: {}, id: "woot_revived:gold_pylon"}},
        {pos: [7, 5, 11], state: "woot_revived:diamond_pylon{attached:true,enabled:true}", nbt: {ForgeCaps: {}, id: "woot_revived:diamond_pylon"}},
        {pos: [8, 5, 6], state: "woot_revived:iron_pylon{attached:true,enabled:true}", nbt: {ForgeCaps: {}, id: "woot_revived:iron_pylon"}},
        {pos: [8, 5, 7], state: "woot_revived:copper_pylon{attached:true,enabled:true}", nbt: {ForgeCaps: {}, id: "woot_revived:copper_pylon"}},
        {pos: [8, 5, 8], state: "woot_revived:copper_pylon{attached:true,enabled:true}", nbt: {ForgeCaps: {}, id: "woot_revived:copper_pylon"}},
        {pos: [8, 5, 9], state: "woot_revived:copper_pylon{attached:true,enabled:true}", nbt: {ForgeCaps: {}, id: "woot_revived:copper_pylon"}},
        {pos: [8, 5, 10], state: "woot_revived:iron_pylon{attached:true,enabled:true}", nbt: {ForgeCaps: {}, id: "woot_revived:iron_pylon"}},
        {pos: [9, 5, 5], state: "woot_revived:diamond_pylon{attached:true,enabled:true}", nbt: {ForgeCaps: {}, id: "woot_revived:diamond_pylon"}},
        {pos: [9, 5, 6], state: "woot_revived:gold_pylon{attached:true,enabled:true}", nbt: {ForgeCaps: {}, id: "woot_revived:gold_pylon"}},
        {pos: [9, 5, 7], state: "woot_revived:iron_pylon{attached:true,enabled:true}", nbt: {ForgeCaps: {}, id: "woot_revived:iron_pylon"}},
        {pos: [9, 5, 8], state: "woot_revived:copper_pylon{attached:true,enabled:true}", nbt: {ForgeCaps: {}, id: "woot_revived:copper_pylon"}},
        {pos: [9, 5, 9], state: "woot_revived:iron_pylon{attached:true,enabled:true}", nbt: {ForgeCaps: {}, id: "woot_revived:iron_pylon"}},
        {pos: [9, 5, 10], state: "woot_revived:gold_pylon{attached:true,enabled:true}", nbt: {ForgeCaps: {}, id: "woot_revived:gold_pylon"}},
        {pos: [9, 5, 11], state: "woot_revived:diamond_pylon{attached:true,enabled:true}", nbt: {ForgeCaps: {}, id: "woot_revived:diamond_pylon"}},
        {pos: [10, 5, 5], state: "woot_revived:diamond_pylon{attached:true,enabled:true}", nbt: {ForgeCaps: {}, id: "woot_revived:diamond_pylon"}},
        {pos: [10, 5, 6], state: "woot_revived:gold_pylon{attached:true,enabled:true}", nbt: {ForgeCaps: {}, id: "woot_revived:gold_pylon"}},
        {pos: [10, 5, 7], state: "woot_revived:gold_pylon{attached:true,enabled:true}", nbt: {ForgeCaps: {}, id: "woot_revived:gold_pylon"}},
        {pos: [10, 5, 8], state: "woot_revived:iron_pylon{attached:true,enabled:true}", nbt: {ForgeCaps: {}, id: "woot_revived:iron_pylon"}},
        {pos: [10, 5, 9], state: "woot_revived:gold_pylon{attached:true,enabled:true}", nbt: {ForgeCaps: {}, id: "woot_revived:gold_pylon"}},
        {pos: [10, 5, 10], state: "woot_revived:gold_pylon{attached:true,enabled:true}", nbt: {ForgeCaps: {}, id: "woot_revived:gold_pylon"}},
        {pos: [10, 5, 11], state: "woot_revived:diamond_pylon{attached:true,enabled:true}", nbt: {ForgeCaps: {}, id: "woot_revived:diamond_pylon"}},
        {pos: [11, 5, 6], state: "woot_revived:diamond_pylon{attached:true,enabled:true}", nbt: {ForgeCaps: {}, id: "woot_revived:diamond_pylon"}},
        {pos: [11, 5, 7], state: "woot_revived:diamond_pylon{attached:true,enabled:true}", nbt: {ForgeCaps: {}, id: "woot_revived:diamond_pylon"}},
        {pos: [11, 5, 9], state: "woot_revived:diamond_pylon{attached:true,enabled:true}", nbt: {ForgeCaps: {}, id: "woot_revived:diamond_pylon"}},
        {pos: [11, 5, 10], state: "woot_revived:diamond_pylon{attached:true,enabled:true}", nbt: {ForgeCaps: {}, id: "woot_revived:diamond_pylon"}},
        {pos: [5, 6, 6], state: "woot_revived:diamond_pylon{attached:true,enabled:true}", nbt: {ForgeCaps: {}, id: "woot_revived:diamond_pylon"}},
        {pos: [5, 6, 7], state: "woot_revived:diamond_pylon{attached:true,enabled:true}", nbt: {ForgeCaps: {}, id: "woot_revived:diamond_pylon"}},
        {pos: [5, 6, 9], state: "woot_revived:diamond_pylon{attached:true,enabled:true}", nbt: {ForgeCaps: {}, id: "woot_revived:diamond_pylon"}},
        {pos: [5, 6, 10], state: "woot_revived:diamond_pylon{attached:true,enabled:true}", nbt: {ForgeCaps: {}, id: "woot_revived:diamond_pylon"}},
        {pos: [6, 6, 5], state: "woot_revived:diamond_pylon{attached:true,enabled:true}", nbt: {ForgeCaps: {}, id: "woot_revived:diamond_pylon"}},
        {pos: [6, 6, 6], state: "woot_revived:gold_pylon{attached:true,enabled:true}", nbt: {ForgeCaps: {}, id: "woot_revived:gold_pylon"}},
        {pos: [6, 6, 7], state: "woot_revived:gold_pylon{attached:true,enabled:true}", nbt: {ForgeCaps: {}, id: "woot_revived:gold_pylon"}},
        {pos: [6, 6, 8], state: "woot_revived:factory_ctr_base_sec{attached:true,enabled:true}", nbt: {ForgeCaps: {}, id: "woot_revived:factory_ctr_base_sec"}},
        {pos: [6, 6, 9], state: "woot_revived:gold_pylon{attached:true,enabled:true}", nbt: {ForgeCaps: {}, id: "woot_revived:gold_pylon"}},
        {pos: [6, 6, 10], state: "woot_revived:gold_pylon{attached:true,enabled:true}", nbt: {ForgeCaps: {}, id: "woot_revived:gold_pylon"}},
        {pos: [6, 6, 11], state: "woot_revived:diamond_pylon{attached:true,enabled:true}", nbt: {ForgeCaps: {}, id: "woot_revived:diamond_pylon"}},
        {pos: [7, 6, 5], state: "woot_revived:diamond_pylon{attached:true,enabled:true}", nbt: {ForgeCaps: {}, id: "woot_revived:diamond_pylon"}},
        {pos: [7, 6, 6], state: "woot_revived:gold_pylon{attached:true,enabled:true}", nbt: {ForgeCaps: {}, id: "woot_revived:gold_pylon"}},
        {pos: [7, 6, 7], state: "woot_revived:iron_pylon{attached:true,enabled:true}", nbt: {ForgeCaps: {}, id: "woot_revived:iron_pylon"}},
        {pos: [7, 6, 8], state: "woot_revived:copper_pylon{attached:true,enabled:true}", nbt: {ForgeCaps: {}, id: "woot_revived:copper_pylon"}},
        {pos: [7, 6, 9], state: "woot_revived:iron_pylon{attached:true,enabled:true}", nbt: {ForgeCaps: {}, id: "woot_revived:iron_pylon"}},
        {pos: [7, 6, 10], state: "woot_revived:gold_pylon{attached:true,enabled:true}", nbt: {ForgeCaps: {}, id: "woot_revived:gold_pylon"}},
        {pos: [7, 6, 11], state: "woot_revived:diamond_pylon{attached:true,enabled:true}", nbt: {ForgeCaps: {}, id: "woot_revived:diamond_pylon"}},
        {pos: [8, 6, 6], state: "woot_revived:factory_ctr_base_pri{attached:true,enabled:true}", nbt: {ForgeCaps: {}, id: "woot_revived:factory_ctr_base_pri"}},
        {pos: [8, 6, 7], state: "woot_revived:copper_pylon{attached:true,enabled:true}", nbt: {ForgeCaps: {}, id: "woot_revived:copper_pylon"}},
        {pos: [8, 6, 8], state: "woot_revived:copper_pylon{attached:true,enabled:true}", nbt: {ForgeCaps: {}, id: "woot_revived:copper_pylon"}},
        {pos: [8, 6, 9], state: "woot_revived:copper_pylon{attached:true,enabled:true}", nbt: {ForgeCaps: {}, id: "woot_revived:copper_pylon"}},
        {pos: [8, 6, 10], state: "woot_revived:factory_ctr_base_sec{attached:true,enabled:true}", nbt: {ForgeCaps: {}, id: "woot_revived:factory_ctr_base_sec"}},
        {pos: [9, 6, 5], state: "woot_revived:diamond_pylon{attached:true,enabled:true}", nbt: {ForgeCaps: {}, id: "woot_revived:diamond_pylon"}},
        {pos: [9, 6, 6], state: "woot_revived:gold_pylon{attached:true,enabled:true}", nbt: {ForgeCaps: {}, id: "woot_revived:gold_pylon"}},
        {pos: [9, 6, 7], state: "woot_revived:iron_pylon{attached:true,enabled:true}", nbt: {ForgeCaps: {}, id: "woot_revived:iron_pylon"}},
        {pos: [9, 6, 8], state: "woot_revived:copper_pylon{attached:true,enabled:true}", nbt: {ForgeCaps: {}, id: "woot_revived:copper_pylon"}},
        {pos: [9, 6, 9], state: "woot_revived:iron_pylon{attached:true,enabled:true}", nbt: {ForgeCaps: {}, id: "woot_revived:iron_pylon"}},
        {pos: [9, 6, 10], state: "woot_revived:gold_pylon{attached:true,enabled:true}", nbt: {ForgeCaps: {}, id: "woot_revived:gold_pylon"}},
        {pos: [9, 6, 11], state: "woot_revived:diamond_pylon{attached:true,enabled:true}", nbt: {ForgeCaps: {}, id: "woot_revived:diamond_pylon"}},
        {pos: [10, 6, 5], state: "woot_revived:diamond_pylon{attached:true,enabled:true}", nbt: {ForgeCaps: {}, id: "woot_revived:diamond_pylon"}},
        {pos: [10, 6, 6], state: "woot_revived:gold_pylon{attached:true,enabled:true}", nbt: {ForgeCaps: {}, id: "woot_revived:gold_pylon"}},
        {pos: [10, 6, 7], state: "woot_revived:gold_pylon{attached:true,enabled:true}", nbt: {ForgeCaps: {}, id: "woot_revived:gold_pylon"}},
        {pos: [10, 6, 8], state: "woot_revived:factory_ctr_base_sec{attached:true,enabled:true}", nbt: {ForgeCaps: {}, id: "woot_revived:factory_ctr_base_sec"}},
        {pos: [10, 6, 9], state: "woot_revived:gold_pylon{attached:true,enabled:true}", nbt: {ForgeCaps: {}, id: "woot_revived:gold_pylon"}},
        {pos: [10, 6, 10], state: "woot_revived:gold_pylon{attached:true,enabled:true}", nbt: {ForgeCaps: {}, id: "woot_revived:gold_pylon"}},
        {pos: [10, 6, 11], state: "woot_revived:diamond_pylon{attached:true,enabled:true}", nbt: {ForgeCaps: {}, id: "woot_revived:diamond_pylon"}},
        {pos: [11, 6, 6], state: "woot_revived:diamond_pylon{attached:true,enabled:true}", nbt: {ForgeCaps: {}, id: "woot_revived:diamond_pylon"}},
        {pos: [11, 6, 7], state: "woot_revived:diamond_pylon{attached:true,enabled:true}", nbt: {ForgeCaps: {}, id: "woot_revived:diamond_pylon"}},
        {pos: [11, 6, 9], state: "woot_revived:diamond_pylon{attached:true,enabled:true}", nbt: {ForgeCaps: {}, id: "woot_revived:diamond_pylon"}},
        {pos: [11, 6, 10], state: "woot_revived:diamond_pylon{attached:true,enabled:true}", nbt: {ForgeCaps: {}, id: "woot_revived:diamond_pylon"}},
        {pos: [5, 7, 6], state: "woot_revived:diamond_plinth{attached:true,enabled:true}", nbt: {ForgeCaps: {}, id: "woot_revived:diamond_plinth"}},
        {pos: [5, 7, 7], state: "woot_revived:diamond_plinth{attached:true,enabled:true}", nbt: {ForgeCaps: {}, id: "woot_revived:diamond_plinth"}},
        {pos: [5, 7, 9], state: "woot_revived:diamond_plinth{attached:true,enabled:true}", nbt: {ForgeCaps: {}, id: "woot_revived:diamond_plinth"}},
        {pos: [5, 7, 10], state: "woot_revived:diamond_plinth{attached:true,enabled:true}", nbt: {ForgeCaps: {}, id: "woot_revived:diamond_plinth"}},
        {pos: [6, 7, 5], state: "woot_revived:diamond_plinth{attached:true,enabled:true}", nbt: {ForgeCaps: {}, id: "woot_revived:diamond_plinth"}},
        {pos: [6, 7, 6], state: "woot_revived:gold_pylon{attached:true,enabled:true}", nbt: {ForgeCaps: {}, id: "woot_revived:gold_pylon"}},
        {pos: [6, 7, 7], state: "woot_revived:gold_pylon{attached:true,enabled:true}", nbt: {ForgeCaps: {}, id: "woot_revived:gold_pylon"}},
        {pos: [6, 7, 8], state: "woot_revived:fake_spawner{attached:true,enabled:false}", nbt: {Accumulator: 0.0d, ForgeCaps: {}, NumOfSim: 0, PerTickRatio: 0.0d, TotalDrained: 0, VitalityCost: 0, id: "woot_revived:fake_spawner"}},
        {pos: [6, 7, 9], state: "woot_revived:gold_pylon{attached:true,enabled:true}", nbt: {ForgeCaps: {}, id: "woot_revived:gold_pylon"}},
        {pos: [6, 7, 10], state: "woot_revived:gold_pylon{attached:true,enabled:true}", nbt: {ForgeCaps: {}, id: "woot_revived:gold_pylon"}},
        {pos: [6, 7, 11], state: "woot_revived:diamond_plinth{attached:true,enabled:true}", nbt: {ForgeCaps: {}, id: "woot_revived:diamond_plinth"}},
        {pos: [7, 7, 5], state: "woot_revived:diamond_plinth{attached:true,enabled:true}", nbt: {ForgeCaps: {}, id: "woot_revived:diamond_plinth"}},
        {pos: [7, 7, 6], state: "woot_revived:gold_pylon{attached:true,enabled:true}", nbt: {ForgeCaps: {}, id: "woot_revived:gold_pylon"}},
        {pos: [7, 7, 7], state: "woot_revived:iron_pylon{attached:true,enabled:true}", nbt: {ForgeCaps: {}, id: "woot_revived:iron_pylon"}},
        {pos: [7, 7, 8], state: "woot_revived:copper_pylon{attached:true,enabled:true}", nbt: {ForgeCaps: {}, id: "woot_revived:copper_pylon"}},
        {pos: [7, 7, 9], state: "woot_revived:iron_pylon{attached:true,enabled:true}", nbt: {ForgeCaps: {}, id: "woot_revived:iron_pylon"}},
        {pos: [7, 7, 10], state: "woot_revived:gold_pylon{attached:true,enabled:true}", nbt: {ForgeCaps: {}, id: "woot_revived:gold_pylon"}},
        {pos: [7, 7, 11], state: "woot_revived:diamond_plinth{attached:true,enabled:true}", nbt: {ForgeCaps: {}, id: "woot_revived:diamond_plinth"}},
        {pos: [8, 7, 6], state: "woot_revived:fake_spawner{attached:true,enabled:true}", nbt: {Accumulator: 0.0d, ForgeCaps: {}, Mob: {id: "minecraft:pig"}, NumOfSim: 1, PerTickRatio: 2.5d, TotalDrained: 0, VitalityCost: 1000, id: "woot_revived:fake_spawner"}},
        {pos: [8, 7, 7], state: "woot_revived:copper_pylon{attached:true,enabled:true}", nbt: {ForgeCaps: {}, id: "woot_revived:copper_pylon"}},
        {pos: [8, 7, 8], state: "woot_revived:copper_pylon{attached:true,enabled:true}", nbt: {ForgeCaps: {}, id: "woot_revived:copper_pylon"}},
        {pos: [8, 7, 9], state: "woot_revived:copper_pylon{attached:true,enabled:true}", nbt: {ForgeCaps: {}, id: "woot_revived:copper_pylon"}},
        {pos: [8, 7, 10], state: "woot_revived:fake_spawner{attached:true,enabled:false}", nbt: {Accumulator: 0.0d, ForgeCaps: {}, NumOfSim: 0, PerTickRatio: 0.0d, TotalDrained: 0, VitalityCost: 0, id: "woot_revived:fake_spawner"}},
        {pos: [9, 7, 5], state: "woot_revived:diamond_plinth{attached:true,enabled:true}", nbt: {ForgeCaps: {}, id: "woot_revived:diamond_plinth"}},
        {pos: [9, 7, 6], state: "woot_revived:gold_pylon{attached:true,enabled:true}", nbt: {ForgeCaps: {}, id: "woot_revived:gold_pylon"}},
        {pos: [9, 7, 7], state: "woot_revived:iron_pylon{attached:true,enabled:true}", nbt: {ForgeCaps: {}, id: "woot_revived:iron_pylon"}},
        {pos: [9, 7, 8], state: "woot_revived:copper_pylon{attached:true,enabled:true}", nbt: {ForgeCaps: {}, id: "woot_revived:copper_pylon"}},
        {pos: [9, 7, 9], state: "woot_revived:iron_pylon{attached:true,enabled:true}", nbt: {ForgeCaps: {}, id: "woot_revived:iron_pylon"}},
        {pos: [9, 7, 10], state: "woot_revived:gold_pylon{attached:true,enabled:true}", nbt: {ForgeCaps: {}, id: "woot_revived:gold_pylon"}},
        {pos: [9, 7, 11], state: "woot_revived:diamond_plinth{attached:true,enabled:true}", nbt: {ForgeCaps: {}, id: "woot_revived:diamond_plinth"}},
        {pos: [10, 7, 5], state: "woot_revived:diamond_plinth{attached:true,enabled:true}", nbt: {ForgeCaps: {}, id: "woot_revived:diamond_plinth"}},
        {pos: [10, 7, 6], state: "woot_revived:gold_pylon{attached:true,enabled:true}", nbt: {ForgeCaps: {}, id: "woot_revived:gold_pylon"}},
        {pos: [10, 7, 7], state: "woot_revived:gold_pylon{attached:true,enabled:true}", nbt: {ForgeCaps: {}, id: "woot_revived:gold_pylon"}},
        {pos: [10, 7, 8], state: "woot_revived:fake_spawner{attached:true,enabled:false}", nbt: {Accumulator: 0.0d, ForgeCaps: {}, NumOfSim: 0, PerTickRatio: 0.0d, TotalDrained: 0, VitalityCost: 0, id: "woot_revived:fake_spawner"}},
        {pos: [10, 7, 9], state: "woot_revived:gold_pylon{attached:true,enabled:true}", nbt: {ForgeCaps: {}, id: "woot_revived:gold_pylon"}},
        {pos: [10, 7, 10], state: "woot_revived:gold_pylon{attached:true,enabled:true}", nbt: {ForgeCaps: {}, id: "woot_revived:gold_pylon"}},
        {pos: [10, 7, 11], state: "woot_revived:diamond_plinth{attached:true,enabled:true}", nbt: {ForgeCaps: {}, id: "woot_revived:diamond_plinth"}},
        {pos: [11, 7, 6], state: "woot_revived:diamond_plinth{attached:true,enabled:true}", nbt: {ForgeCaps: {}, id: "woot_revived:diamond_plinth"}},
        {pos: [11, 7, 7], state: "woot_revived:diamond_plinth{attached:true,enabled:true}", nbt: {ForgeCaps: {}, id: "woot_revived:diamond_plinth"}},
        {pos: [11, 7, 9], state: "woot_revived:diamond_plinth{attached:true,enabled:true}", nbt: {ForgeCaps: {}, id: "woot_revived:diamond_plinth"}},
        {pos: [11, 7, 10], state: "woot_revived:diamond_plinth{attached:true,enabled:true}", nbt: {ForgeCaps: {}, id: "woot_revived:diamond_plinth"}},
        {pos: [6, 8, 6], state: "woot_revived:gold_plinth{attached:true,enabled:true}", nbt: {ForgeCaps: {}, id: "woot_revived:gold_plinth"}},
        {pos: [6, 8, 7], state: "woot_revived:gold_plinth{attached:true,enabled:true}", nbt: {ForgeCaps: {}, id: "woot_revived:gold_plinth"}},
        {pos: [6, 8, 9], state: "woot_revived:gold_plinth{attached:true,enabled:true}", nbt: {ForgeCaps: {}, id: "woot_revived:gold_plinth"}},
        {pos: [6, 8, 10], state: "woot_revived:gold_plinth{attached:true,enabled:true}", nbt: {ForgeCaps: {}, id: "woot_revived:gold_plinth"}},
        {pos: [7, 8, 6], state: "woot_revived:gold_plinth{attached:true,enabled:true}", nbt: {ForgeCaps: {}, id: "woot_revived:gold_plinth"}},
        {pos: [7, 8, 7], state: "woot_revived:iron_pylon{attached:true,enabled:true}", nbt: {ForgeCaps: {}, id: "woot_revived:iron_pylon"}},
        {pos: [7, 8, 8], state: "woot_revived:factory_upgrade{attached:true,enabled:true}", nbt: {ForgeCaps: {}, UpgradeItem: "", id: "woot_revived:factory_upgrade"}},
        {pos: [7, 8, 9], state: "woot_revived:iron_pylon{attached:true,enabled:true}", nbt: {ForgeCaps: {}, id: "woot_revived:iron_pylon"}},
        {pos: [7, 8, 10], state: "woot_revived:gold_plinth{attached:true,enabled:true}", nbt: {ForgeCaps: {}, id: "woot_revived:gold_plinth"}},
        {pos: [8, 8, 7], state: "woot_revived:factory_upgrade{attached:true,enabled:true}", nbt: {ForgeCaps: {}, UpgradeItem: "", id: "woot_revived:factory_upgrade"}},
        {pos: [8, 8, 8], state: "woot_revived:copper_pylon{attached:true,enabled:true}", nbt: {ForgeCaps: {}, id: "woot_revived:copper_pylon"}},
        {pos: [8, 8, 9], state: "woot_revived:factory_upgrade{attached:true,enabled:true}", nbt: {ForgeCaps: {}, UpgradeItem: "", id: "woot_revived:factory_upgrade"}},
        {pos: [9, 8, 6], state: "woot_revived:gold_plinth{attached:true,enabled:true}", nbt: {ForgeCaps: {}, id: "woot_revived:gold_plinth"}},
        {pos: [9, 8, 7], state: "woot_revived:iron_pylon{attached:true,enabled:true}", nbt: {ForgeCaps: {}, id: "woot_revived:iron_pylon"}},
        {pos: [9, 8, 8], state: "woot_revived:factory_upgrade{attached:true,enabled:true}", nbt: {ForgeCaps: {}, UpgradeItem: "", id: "woot_revived:factory_upgrade"}},
        {pos: [9, 8, 9], state: "woot_revived:iron_pylon{attached:true,enabled:true}", nbt: {ForgeCaps: {}, id: "woot_revived:iron_pylon"}},
        {pos: [9, 8, 10], state: "woot_revived:gold_plinth{attached:true,enabled:true}", nbt: {ForgeCaps: {}, id: "woot_revived:gold_plinth"}},
        {pos: [10, 8, 6], state: "woot_revived:gold_plinth{attached:true,enabled:true}", nbt: {ForgeCaps: {}, id: "woot_revived:gold_plinth"}},
        {pos: [10, 8, 7], state: "woot_revived:gold_plinth{attached:true,enabled:true}", nbt: {ForgeCaps: {}, id: "woot_revived:gold_plinth"}},
        {pos: [10, 8, 9], state: "woot_revived:gold_plinth{attached:true,enabled:true}", nbt: {ForgeCaps: {}, id: "woot_revived:gold_plinth"}},
        {pos: [10, 8, 10], state: "woot_revived:gold_plinth{attached:true,enabled:true}", nbt: {ForgeCaps: {}, id: "woot_revived:gold_plinth"}},
        {pos: [7, 9, 7], state: "woot_revived:iron_plinth{attached:true,enabled:true}", nbt: {ForgeCaps: {}, id: "woot_revived:iron_plinth"}},
        {pos: [7, 9, 9], state: "woot_revived:iron_plinth{attached:true,enabled:true}", nbt: {ForgeCaps: {}, id: "woot_revived:iron_plinth"}},
        {pos: [8, 9, 7], state: "woot_revived:heart{enabled:true,facing:north}", nbt: {ForgeCaps: {}, Tier: 4, id: "woot_revived:heart"}},
        {pos: [8, 9, 8], state: "woot_revived:copper_pylon{attached:true,enabled:true}", nbt: {ForgeCaps: {}, id: "woot_revived:copper_pylon"}},
        {pos: [9, 9, 7], state: "woot_revived:iron_plinth{attached:true,enabled:true}", nbt: {ForgeCaps: {}, id: "woot_revived:iron_plinth"}},
        {pos: [9, 9, 9], state: "woot_revived:iron_plinth{attached:true,enabled:true}", nbt: {ForgeCaps: {}, id: "woot_revived:iron_plinth"}},
        {pos: [8, 10, 8], state: "woot_revived:copper_plinth{attached:true,enabled:true}", nbt: {ForgeCaps: {}, id: "woot_revived:copper_plinth"}}
    ],
    entities: [],
    palette: [
        "woot_revived:diamond_cell{attached:true,enabled:true}",
        "woot_revived:export{attached:true,enabled:true}",
        "woot_revived:import{attached:true,enabled:true}",
        "woot_revived:factory_connect{attached:true,enabled:true}",
        "woot_revived:diamond_plinth{attached:true,enabled:true}",
        "woot_revived:gold_plinth{attached:true,enabled:true}",
        "woot_revived:iron_plinth{attached:true,enabled:true}",
        "woot_revived:copper_plinth{attached:true,enabled:true}",
        "woot_revived:diamond_pylon{attached:true,enabled:true}",
        "woot_revived:gold_pylon{attached:true,enabled:true}",
        "woot_revived:iron_pylon{attached:true,enabled:true}",
        "woot_revived:copper_pylon{attached:true,enabled:true}",
        "woot_revived:factory_ctr_base_sec{attached:true,enabled:true}",
        "woot_revived:factory_ctr_base_pri{attached:true,enabled:true}",
        "woot_revived:fake_spawner{attached:true,enabled:false}",
        "woot_revived:fake_spawner{attached:true,enabled:true}",
        "woot_revived:factory_upgrade{attached:true,enabled:true}",
        "woot_revived:heart{enabled:true,facing:north}"
    ]
}